Workbook

Sheet Raw_Data
A1: Timestamp | B1: Username | C1: Mobile Network Provider / OpÃ©rateur mobile | D1: Where do you mostly use mobile data? / OÃ¹ utilisez-vous le plus Internet mobile ? | E1: What type of phone do you use? / Quel type de tÃ©lÃ©phone utilisez-vous ? | F1: Please what is your age range | G1: How often do you use mobile internet? / Ã€ quelle frÃ©quence utilisez-vous Internet mobile ? | H1: What do you mainly use mobile data for? / Ã€ quoi utilisez-vous principalement Internet mobile ? | I1: Overall, how is your mobile network experience? / Globalement, comment est votre expÃ©rience rÃ©seau ? | J1: How would you rate your internet speed? / Comment Ã©valuez-vous la vitesse de votre Internet ? | K1: How reliable is your connection (few disconnections)? / Votre connexion est-elle stable (peu de coupures) ? | L1: How often do videos buffer (pause to load)? / Ã€ quelle frÃ©quence les vidÃ©os se mettent en pause (chargement) ? | M1: What problem do you experience most? / Quel problÃ¨me rencontrez-vous le plus ? | N1: How often do these problems occur? / Ã€ quelle frÃ©quence ces problÃ¨mes surviennent-ils ? | O1: When is the network worst? / Quand le rÃ©seau est-il le plus mauvais ? | P1: Where do you experience the most problems? / OÃ¹ rencontrez-vous le plus de problÃ¨mes ? | Q1: How strong is your signal most of the time? / Quelle est la force du signal la plupart du temps ? | R1: How much does poor network affect your daily activities? / Ã€ quel point le mauvais rÃ©seau affecte vos activitÃ©s quotidiennes ? | S1: Would you use an app that monitors your network quality? / Utiliseriez-vous une application qui analyse votre rÃ©seau ? | T1: Are you willing to allow automatic data collection (network performance)? / Acceptez-vous la collecte automatique des donnÃ©es rÃ©seau ? | U1: How often should the app ask for feedback? / Ã€ quelle frÃ©quence lâ€™application doit-elle demander votre avis ? | V1: Are you comfortable sharing your location? / ÃŠtes-vous dâ€™accord pour partager votre localisation ? | W1: What concerns do you have? / Quelles sont vos prÃ©occupations ?
A2: 2026/04/23 10:31:16 PM GMT+1 | B2: yasiritemwa233@gmail.com | C2: Orange | D2: Southwest Region | E2: Android | F2: 20-25 | G2: Very often / TrÃ¨s souvent | H2: Browsing / Navigation | I2: Poor / Mauvaise | J2: 2 | K2: Poor / Instable | L2: Often / Souvent | M2: Slow internet / Internet lent | N2: Often / Souvent | O2: Night / Nuit | P2: Everywhere / Partout | Q2: Weak / Faible | R2: Severely / Beaucoup | S2: Yes / Oui | T2: Yes / Oui | U2: Once a day / Une fois par jour | V2: Yes / Oui | W2: Battery usage / Batterie;Data usage / Consommation de donnÃ©es;Security / SÃ©curitÃ© | X2: Battery usage / Batterie;Data usage / Consommation de donnÃ©es;Security / SÃ©curitÃ©
A3: 2026/04/23 10:54:23 PM GMT+1 | B3: maagboramelia123@gmail.com | C3: MTN | D3: Southwest Region | E3: Android | F3: 20-25 | G3: Very often / TrÃ¨s souvent | H3: Social media / RÃ©seaux sociaux | I3: Very Poor / TrÃ¨s mauvaise | J3: 3 | K3: Very Poor / TrÃ¨s instable | L3: Often / Souvent | M3: Slow internet / Internet lent | N3: Very often / TrÃ¨s souvent | O3: Night / Nuit | P3: Everywhere / Partout | Q3: Moderate / Moyen | R3: Severely / Beaucoup | S3: No / Non | T3: No / Non | U3: Never / Jamais | V3: No / Non | W3: Privacy / ConfidentialitÃ©;Battery usage / Batterie;Security / SÃ©curitÃ© | X3: Privacy / ConfidentialitÃ©
A4: 2026/04/23 11:07:04 PM GMT+1 | B4: yvettecrystal24@gmail.com | C4: MTN;Orange | D4: North West Region | E4: iPhone | F4: 20-25 | G4: Very often / TrÃ¨s souvent | H4: Social media / RÃ©seaux sociaux;Messaging / Messagerie (WhatsApp, etc.);Online classes/work / Cours ou travail en ligne;Gaming / Jeux;Browsing / Navigation | I4: Average / Moyenne | J4: 3 | K4: Average / Moyenne | L4: Sometimes / Parfois | M4: Slow internet / Internet lent;No signal / Pas de rÃ©seau | N4: Often / Souvent | O4: Afternoon / AprÃ¨s-midi | P4: Everywhere / Partout | Q4: Moderate / Moyen | R4: Moderately / Moyennement | S4: Yes / Oui | T4: Yes / Oui | U4: Once a day / Une fois par jour | V4: Yes / Oui | W4: Privacy / ConfidentialitÃ©;Data usage / Consommation de donnÃ©es;Security / SÃ©curitÃ© | X4: Privacy / ConfidentialitÃ©;Data usage / Consommation de donnÃ©es;Security / SÃ©curitÃ©
A5: 2026/04/23 11:18:50 PM GMT+1 | B5: bjuclear@gmail.com | C5: MTN | D5: Southwest Region | E5: Android | F5: 20-25 | G5: Very often / TrÃ¨s souvent | H5: Social media / RÃ©seaux sociaux | I5: Poor / Mauvaise;Average / Moyenne | J5: 3 | K5: Average / Moyenne | L5: Sometimes / Parfois | M5: Slow internet / Internet lent | N5: Often / Souvent | O5: Evening / Soir | P5: School/Work / Ã‰cole/Travail | Q5: Moderate / Moyen | R5: Severely / Beaucoup | S5: Yes / Oui | T5: Yes / Oui | U5: Only when there is a problem / Seulement en cas de problÃ¨me | V5: Yes / Oui | W5: Privacy / ConfidentialitÃ©;Battery usage / Batterie;Data usage / Consommation de donnÃ©es;Security / SÃ©curitÃ© | X5: Security / SÃ©curitÃ©
A6: 2026/04/23 11:25:07 PM GMT+1 | B6: fulopila9@gmail.com | C6: MTN;Orange;Camtel | D6: Southwest Region | E6: Android;iPhone | F6: 25 and above | G6: Very often / TrÃ¨s souvent | H6: Social media / RÃ©seaux sociaux;Messaging / Messagerie (WhatsApp, etc.);Browsing / Navigation;Software development | I6: Average / Moyenne | J6: 2 | K6: Poor / Instable | L6: Often / Souvent | M6: Slow internet / Internet lent;Call drops / Coupures d'appel;No signal / Pas de rÃ©seau;Poor call quality / Mauvaise qualitÃ© dâ€™appel;Network outages / Pannes rÃ©seau | N6: Often / Souvent | O6: Afternoon / AprÃ¨s-midi | P6: Everywhere / Partout | Q6: Moderate / Moyen | R6: Severely / Beaucoup | S6: Yes / Oui | T6: Yes / Oui | U6: Only when there is a problem / Seulement en cas de problÃ¨me | V6: Yes / Oui | W6: Privacy / ConfidentialitÃ©;Data usage / Consommation de donnÃ©es;Security / SÃ©curitÃ© | X6: Privacy / ConfidentialitÃ©;Data usage / Consommation de donnÃ©es;Security / SÃ©curitÃ©
A7: 2026/04/23 11:25:43 PM GMT+1 | B7: tafopaabigail11@gmail.com | C7: MTN | D7: Center Regional | E7: Android | F7: 15-20 | G7: Very often / TrÃ¨s souvent | H7: Social media / RÃ©seaux sociaux;Online classes/work / Cours ou travail en ligne | I7: Average / Moyenne | J7: 2 | K7: Average / Moyenne | L7: Always / Toujours | M7: Slow internet / Internet lent;No signal / Pas de rÃ©seau;Network outages / Pannes rÃ©seau | N7: Very often / TrÃ¨s souvent | O7: Afternoon / AprÃ¨s-midi | P7: School/Work / Ã‰cole/Travail | Q7: Strong / Fort | R7: Severely / Beaucoup | S7: Yes / Oui | T7: No / Non | U7: Only when there is a problem / Seulement en cas de problÃ¨me | V7: No / Non | W7: Privacy / ConfidentialitÃ©;Security / SÃ©curitÃ© | X7: Data usage / Consommation de donnÃ©es;Security / SÃ©curitÃ©
A8: 2026/04/23 11:26:31 PM GMT+1 | B8: nkengafac.madelene.olive@gmail.com | C8: MTN | D8: Southwest Region | E8: Android | F8: 20-25 | G8: Often / Souvent | H8: Messaging / Messagerie (WhatsApp, etc.);Browsing / Navigation | I8: Poor / Mauvaise | J8: 1 | K8: Poor / Instable | L8: Always / Toujours | M8: Slow internet / Internet lent;Call drops / Coupures d'appel;No signal / Pas de rÃ©seau;Poor call quality / Mauvaise qualitÃ© dâ€™appel | N8: Often / Souvent | O8: Afternoon / AprÃ¨s-midi | P8: School/Work / Ã‰cole/Travail | Q8: Weak / Faible | R8: Severely / Beaucoup | S8: No / Non | T8: No / Non | U8: Every time / Ã€ chaque fois | V8: No / Non | W8: Privacy / ConfidentialitÃ©;Security / SÃ©curitÃ© | X8: Privacy / ConfidentialitÃ©;Security / SÃ©curitÃ©
A9: 2026/04/23 11:34:00 PM GMT+1 | B9: emmanugwe31@gmail.com | C9: MTN;Orange;Camtel | D9: North West Region | E9: Android | F9: 20-25 | G9: Very often / TrÃ¨s souvent | H9: Social media / RÃ©seaux sociaux;Messaging / Messagerie (WhatsApp, etc.);Online classes/work / Cours ou travail en ligne;Browsing / Navigation;Do surveys to help improve network | I9: Average / Moyenne | J9: 3 | K9: Average / Moyenne | L9: Sometimes / Parfois | M9: Slow internet / Internet lent;Network outages / Pannes rÃ©seau | N9: Often / Souvent | O9: Afternoon / AprÃ¨s-midi | P9: Everywhere / Partout | Q9: Moderate / Moyen | R9: Moderately / Moyennement | S9: Yes / Oui | T9: Yes / Oui | U9: Every time / Ã€ chaque fois | V9: Yes / Oui | W9: Privacy / ConfidentialitÃ© | X9: Battery usage / Batterie
A10: 2026/04/24 12:49:27 AM GMT+1 | B10: cristianoace224@gmail.com | C10: MTN;Orange | D10: North Region | E10: Android | F10: 25 and above | G10: Very often / TrÃ¨s souvent | H10: Social media / RÃ©seaux sociaux;Video streaming / VidÃ©o (YouTube, Netflix);Messaging / Messagerie (WhatsApp, etc.);Gaming / Jeux | I10: Average / Moyenne | J10: 3 | K10: Average / Moyenne | L10: Sometimes / Parfois | M10: No signal / Pas de rÃ©seau | N10: Sometimes / Parfois | O10: Afternoon / AprÃ¨s-midi | P10: Everywhere / Partout | Q10: Moderate / Moyen | R10: Severely / Beaucoup | S10: No / Non | T10: No / Non | U10: Only when there is a problem / Seulement en cas de problÃ¨me | V10: No / Non | W10: None / Aucune | X10: None / Aucune
A11: 2026/04/24 12:54:34 AM GMT+1 | B11: isaiahafese@gmail.com | C11: MTN | D11: North West Region | E11: iPhone | F11: 15-20 | G11: Very often / TrÃ¨s souvent | H11: Classified | I11: Good / Bonne | J11: 4 | K11: Good / Stable | L11: Never / Jamais | M11: Slow internet / Internet lent | N11: Sometimes / Parfois | O11: Afternoon / AprÃ¨s-midi | P11: School/Work / Ã‰cole/Travail | Q11: Moderate / Moyen | R11: Severely / Beaucoup | S11: Yes / Oui | T11: No / Non | U11: Once a day / Une fois par jour | V11: No / Non | W11: Privacy / ConfidentialitÃ© | X11: Privacy / ConfidentialitÃ©
A12: 2026/04/24 1:01:49 AM GMT+1 | B12: teyimdiane@gmail.com | C12: MTN | D12: Southwest Region | E12: iPhone | F12: 20-25 | G12: Very often / TrÃ¨s souvent | H12: Social media / RÃ©seaux sociaux;Messaging / Messagerie (WhatsApp, etc.) | I12: Poor / Mauvaise | J12: 3 | K12: Poor / Instable | L12: Often / Souvent | M12: Slow internet / Internet lent;No signal / Pas de rÃ©seau;Poor call quality / Mauvaise qualitÃ© dâ€™appel | N12: Sometimes / Parfois | O12: Afternoon / AprÃ¨s-midi | P12: Everywhere / Partout | Q12: Moderate / Moyen | R12: Moderately / Moyennement | S12: Yes / Oui | T12: No / Non | U12: Only when there is a problem / Seulement en cas de problÃ¨me | V12: No / Non | W12: Privacy / ConfidentialitÃ© | X12: Security / SÃ©curitÃ©
A13: 2026/04/24 1:44:54 AM GMT+1 | B13: ndanjongdan@gmail.com | C13: MTN | D13: North West Region | E13: Android | F13: 20-25 | G13: Very often / TrÃ¨s souvent | H13: Social media / RÃ©seaux sociaux;Messaging / Messagerie (WhatsApp, etc.);Online classes/work / Cours ou travail en ligne;Browsing / Navigation | I13: Poor / Mauvaise | J13: 2 | K13: Average / Moyenne | L13: Often / Souvent | M13: Slow internet / Internet lent;Poor call quality / Mauvaise qualitÃ© dâ€™appel;Network outages / Pannes rÃ©seau | N13: Often / Souvent | O13: Afternoon / AprÃ¨s-midi | P13: Everywhere / Partout | Q13: Moderate / Moyen | R13: Severely / Beaucoup | S13: Yes / Oui | T13: No / Non | U13: Only when there is a problem / Seulement en cas de problÃ¨me | V13: No / Non | W13: Privacy / ConfidentialitÃ©;Data usage / Consommation de donnÃ©es;Security / SÃ©curitÃ© | X13: Privacy / ConfidentialitÃ©;Data usage / Consommation de donnÃ©es;Security / SÃ©curitÃ©
... A19: 2026/04/24 6:09:53 AM GMT+1 | B19: blessingntenkia@gmail.com | C19: MTN | D19: West Region | E19: Android | F19: 20-25 | G19: Very often / TrÃ¨s souvent;Often / Souvent | H19: Social media / RÃ©seaux sociaux;Messaging / Messagerie (WhatsApp, etc.);Online classes/work / Cours ou travail en ligne | I19: Average / Moyenne | J19: 3 | K19: Average / Moyenne | L19: Sometimes / Parfois | M19: Slow internet / Internet lent | N19: Sometimes / Parfois | O19: Afternoon / AprÃ¨s-midi | P19: Everywhere / Partout | Q19: Moderate / Moyen | R19: Slightly / Un peu | S19: Yes / Oui | T19: No / Non | U19: Only when there is a problem / Seulement en cas de problÃ¨me | V19: No / Non | W19: Privacy / ConfidentialitÃ© | X19: Privacy / ConfidentialitÃ©;Battery usage / Batterie
A20: 2026/04/24 6:36:55 AM GMT+1 | C20: Orange | D20: Southwest Region | E20: Android | F20: 20-25 | G20: Very often / TrÃ¨s souvent | H20: Social media / RÃ©seaux sociaux | I20: Average / Moyenne | J20: 3 | K20: Average / Moyenne | L20: Often / Souvent | M20: Poor call quality / Mauvaise qualitÃ© dâ€™appel | N20: Very often / TrÃ¨s souvent | O20: Evening / Soir | P20: Everywhere / Partout | Q20: Moderate / Moyen | R20: Severely / Beaucoup | S20: Yes / Oui | T20: Yes / Oui | U20: Only when there is a problem / Seulement en cas de problÃ¨me | V20: No / Non | W20: Security / SÃ©curitÃ© | X20: Privacy / ConfidentialitÃ©
A21: 2026/04/24 6:40:40 AM GMT+1 | C21: MTN;Camtel | D21: Southwest Region | E21: Android | F21: 20-25 | G21: Very often / TrÃ¨s souvent | H21: Browsing / Navigation | I21: Very Poor / TrÃ¨s mauvaise | J21: 2 | K21: Poor / Instable | L21: Often / Souvent | M21: No signal / Pas de rÃ©seau | N21: Often / Souvent | O21: Evening / Soir | P21: School/Work / Ã‰cole/Travail | Q21: Weak / Faible | R21: Slightly / Un peu | S21: Yes / Oui | T21: Yes / Oui | U21: Once a day / Une fois par jour | V21: No / Non | W21: Privacy / ConfidentialitÃ©;Data usage / Consommation de donnÃ©es;Security / SÃ©curitÃ© | X21: Privacy / ConfidentialitÃ©;Data usage / Consommation de donnÃ©es;Security / SÃ©curitÃ©
A22: 2026/04/24 6:45:11 AM GMT+1 | C22: MTN | D22: South Region | E22: Android | F22: 15-20 | G22: Very often / TrÃ¨s souvent | H22: Video streaming / VidÃ©o (YouTube, Netflix);Messaging / Messagerie (WhatsApp, etc.);Browsing / Navigation | I22: Poor / Mauvaise | J22: 2 | K22: Poor / Instable;Average / Moyenne | L22: Sometimes / Parfois | M22: Slow internet / Internet lent;Call drops / Coupures d'appel;Poor call quality / Mauvaise qualitÃ© dâ€™appel | N22: Very often / TrÃ¨s souvent | O22: Afternoon / AprÃ¨s-midi | P22: School/Work / Ã‰cole/Travail | Q22: Moderate / Moyen | R22: Slightly / Un peu | S22: Yes / Oui | T22: Yes / Oui | U22: Only when there is a problem / Seulement en cas de problÃ¨me | V22: Yes / Oui | W22: Privacy / ConfidentialitÃ© | X22: Privacy / ConfidentialitÃ©;Battery usage / Batterie;Data usage / Consommation de donnÃ©es
A23: 2026/04/24 6:59:02 AM GMT+1 | C23: MTN | D23: North West Region | E23: Android | F23: 20-25 | G23: Very often / TrÃ¨s souvent | H23: Social media / RÃ©seaux sociaux;Video streaming / VidÃ©o (YouTube, Netflix);Messaging / Messagerie (WhatsApp, etc.);Online classes/work / Cours ou travail en ligne;Browsing / Navigation | I23: Poor / Mauvaise | J23: 2 | K23: Poor / Instable | L23: Often / Souvent | M23: Slow internet / Internet lent | N23: Often / Souvent | O23: Afternoon / AprÃ¨s-midi | P23: Everywhere / Partout | Q23: Moderate / Moyen | R23: Severely / Beaucoup | S23: Yes / Oui | T23: Yes / Oui | U23: Only when there is a problem / Seulement en cas de problÃ¨me | V23: Yes / Oui | W23: Privacy / ConfidentialitÃ©;Security / SÃ©curitÃ© | X23: Privacy / ConfidentialitÃ©;Security / SÃ©curitÃ©
A24: 2026/04/24 7:31:31 AM GMT+1 | C24: MTN | D24: North West Region | E24: Android | F24: 20-25 | G24: Very often / TrÃ¨s souvent | H24: Browsing / Navigation | I24: Average / Moyenne | J24: 4 | K24: Average / Moyenne | L24: Often / Souvent | M24: Slow internet / Internet lent | N24: Often / Souvent | O24: Evening / Soir | P24: School/Work / Ã‰cole/Travail | Q24: Moderate / Moyen | R24: Moderately / Moyennement | S24: Yes / Oui | T24: Yes / Oui | U24: Only when there is a problem / Seulement en cas de problÃ¨me | V24: Yes / Oui | W24: Privacy / ConfidentialitÃ©;Battery usage / Batterie;Data usage / Consommation de donnÃ©es;Security / SÃ©curitÃ© | X24: Privacy / ConfidentialitÃ©;Battery usage / Batterie;Data usage / Consommation de donnÃ©es;Security / SÃ©curitÃ©
A25: 2026/04/24 8:02:52 AM GMT+1 | C25: MTN;Orange | D25: Southwest Region | E25: Android | F25: 20-25 | G25: Very often / TrÃ¨s souvent | H25: Social media / RÃ©seaux sociaux;Video streaming / VidÃ©o (YouTube, Netflix);Messaging / Messagerie (WhatsApp, etc.);Online classes/work / Cours ou travail en ligne;Gaming / Jeux;Browsing / Navigation | I25: Very Poor / TrÃ¨s mauvaise | J25: 2 | K25: Very Poor / TrÃ¨s instable | L25: Always / Toujours | M25: Slow internet / Internet lent;Call drops / Coupures d'appel;No signal / Pas de rÃ©seau;Poor call quality / Mauvaise qualitÃ© dâ€™appel;Network outages / Pannes rÃ©seau | N25: Very often / TrÃ¨s souvent | O25: Night / Nuit | P25: Everywhere / Partout | Q25: Very Weak / TrÃ¨s faible | R25: Severely / Beaucoup | S25: Yes / Oui | T25: Yes / Oui | U25: Once a day / Une fois par jour | V25: Yes / Oui | W25: Privacy / ConfidentialitÃ©;Battery usage / Batterie;Data usage / Consommation de donnÃ©es;Security / SÃ©curitÃ© | X25: Privacy / ConfidentialitÃ©;Battery usage / Batterie;Data usage / Consommation de donnÃ©es;Security / SÃ©curitÃ©;None / Aucune
A26: 2026/04/24 8:17:46 AM GMT+1 | B26: susantakor59@gmail.com | C26: MTN | D26: Southwest Region | E26: Android | F26: 15-20 | G26: Very often / TrÃ¨s souvent | H26: Social media / RÃ©seaux sociaux;Online classes/work / Cours ou travail en ligne | I26: Good / Bonne | J26: 3 | K26: Good / Stable | L26: Often / Souvent | M26: Slow internet / Internet lent | N26: Often / Souvent | O26: Night / Nuit | P26: School/Work / Ã‰cole/Travail | Q26: Moderate / Moyen | R26: Moderately / Moyennement | S26: Yes / Oui | T26: Yes / Oui | U26: Once a day / Une fois par jour | V26: Yes / Oui | W26: Privacy / ConfidentialitÃ©;Battery usage / Batterie | X26: Data usage / Consommation de donnÃ©es
A27: 2026/04/24 8:18:49 AM GMT+1 | B27: rickytabe2@gmail.com | C27: MTN;Orange | D27: Southwest Region | E27: iPhone | F27: 20-25 | G27: Very often / TrÃ¨s souvent | H27: Developing / Developer | I27: Poor / Mauvaise | J27: 2 | K27: Poor / Instable | L27: Often / Souvent | M27: Slow internet / Internet lent | N27: Very often / TrÃ¨s souvent | O27: Night / Nuit | P27: Everywhere / Partout | Q27: Weak / Faible | R27: Severely / Beaucoup | S27: Yes / Oui | T27: Yes / Oui | U27: Only when there is a problem / Seulement en cas de problÃ¨me | V27: Yes / Oui | W27: Privacy / ConfidentialitÃ© | X27: Privacy / ConfidentialitÃ©
A28: 2026/04/24 8:25:11 AM GMT+1 | B28: randybright37@gmail.com | C28: MTN;Orange | D28: North West Region | E28: iPhone | F28: 20-25 | G28: Very often / TrÃ¨s souvent | H28: Social media / RÃ©seaux sociaux;Video streaming / VidÃ©o (YouTube, Netflix);Messaging / Messagerie (WhatsApp, etc.);Online classes/work / Cours ou travail en ligne;Browsing / Navigation | I28: Good / Bonne | J28: 3 | K28: Good / Stable | L28: Often / Souvent | M28: Poor call quality / Mauvaise qualitÃ© dâ€™appel | N28: Often / Souvent | O28: Afternoon / AprÃ¨s-midi | P28: Everywhere / Partout | Q28: Strong / Fort | R28: Moderately / Moyennement | S28: Yes / Oui | T28: Yes / Oui | U28: Only when there is a problem / Seulement en cas de problÃ¨me | V28: Yes / Oui | W28: Privacy / ConfidentialitÃ©;Battery usage / Batterie;Data usage / Consommation de donnÃ©es;Security / SÃ©curitÃ© | X28: Privacy / ConfidentialitÃ©;Battery usage / Batterie;Data usage / Consommation de donnÃ©es;Security / SÃ©curitÃ©
A29: 2026/04/24 8:33:12 AM GMT+1 | B29: yadjanga690@gmail.com | C29: Orange | D29: East Region | E29: Android | F29: 20-25 | G29: Often / Souvent | H29: Messaging / Messagerie (WhatsApp, etc.) | I29: Average / Moyenne | J29: 3 | K29: Poor / Instable | L29: Sometimes / Parfois | M29: Slow internet / Internet lent;Network outages / Pannes rÃ©seau | N29: Very often / TrÃ¨s souvent | O29: Evening / Soir | P29: Everywhere / Partout | Q29: Weak / Faible | R29: Slightly / Un peu | S29: No / Non | T29: No / Non | U29: Only when there is a problem / Seulement en cas de problÃ¨me | V29: No / Non | W29: Data usage / Consommation de donnÃ©es | X29: Data usage / Consommation de donnÃ©es
A30: 2026/04/24 8:34:08 AM GMT+1 | B30: maximilienneweah@gmail.com | C30: Orange | D30: Southwest Region | E30: iPhone | F30: 15-20 | G30: Very often / TrÃ¨s souvent | H30: Social media / RÃ©seaux sociaux;Messaging / Messagerie (WhatsApp, etc.);Online classes/work / Cours ou travail en ligne;Browsing / Navigation | I30: Average / Moyenne | J30: 2 | K30: Average / Moyenne | L30: Often / Souvent | M30: Slow internet / Internet lent;Call drops / Coupures d'appel;No signal / Pas de rÃ©seau;Poor call quality / Mauvaise qualitÃ© dâ€™appel;Network outages / Pannes rÃ©seau | N30: Often / Souvent | O30: Evening / Soir | P30: Everywhere / Partout | Q30: Moderate / Moyen | R30: Severely / Beaucoup | S30: Yes / Oui | T30: Yes / Oui | U30: Once a day / Une fois par jour | V30: Yes / Oui | W30: Privacy / ConfidentialitÃ©;Battery usage / Batterie;Data usage / Consommation de donnÃ©es;Security / SÃ©curitÃ© | X30: Privacy / ConfidentialitÃ©;Battery usage / Batterie;Data usage / Consommation de donnÃ©es;Security / SÃ©curitÃ©
A31: 2026/04/24 8:39:53 AM GMT+1 | B31: christabeltewah191@gmail.com | C31: MTN | D31: North West Region | E31: Android | F31: 25 and above | G31: Very often / TrÃ¨s souvent | H31: Messaging / Messagerie (WhatsApp, etc.) | I31: Very Poor / TrÃ¨s mauvaise | J31: 1 | K31: Very Poor / TrÃ¨s instable | L31: Always / Toujours | M31: Slow internet / Internet lent | N31: Very often / TrÃ¨s souvent | O31: Afternoon / AprÃ¨s-midi | P31: Everywhere / Partout | Q31: Very Weak / TrÃ¨s faible | R31: Severely / Beaucoup | S31: Yes / Oui | T31: Yes / Oui | U31: Only when there is a problem / Seulement en cas de problÃ¨me | V31: Yes / Oui | W31: Data usage / Consommation de donnÃ©es | X31: Data usage / Consommation de donnÃ©es
A32: 2026/04/24 8:40:55 AM GMT+1 | B32: bonmasylvia@gmail.com | C32: MTN | D32: Littoral Region | E32: Android | F32: 25 and above | G32: Very often / TrÃ¨s souvent | H32: Social media / RÃ©seaux sociaux;Video streaming / VidÃ©o (YouTube, Netflix);Messaging / Messagerie (WhatsApp, etc.);Online classes/work / Cours ou travail en ligne;Gaming / Jeux;Browsing / Navigation | I32: Average / Moyenne | J32: 3 | K32: Average / Moyenne | L32: Sometimes / Parfois | M32: Call drops / Coupures d'appel | N32: Sometimes / Parfois | O32: Afternoon / AprÃ¨s-midi | P32: On the road / En dÃ©placement | Q32: Moderate / Moyen | R32: Slightly / Un peu | S32: Yes / Oui | T32: No / Non | U32: Every time / Ã€ chaque fois | V32: No / Non | W32: Privacy / ConfidentialitÃ©;Security / SÃ©curitÃ© | X32: Privacy / ConfidentialitÃ©;Security / SÃ©curitÃ©
A33: 2026/04/24 8:45:05 AM GMT+1 | B33: jamisonntuv@gmail.com | C33: MTN | D33: South Region | E33: Android | F33: 20-25 | G33: Very often / TrÃ¨s souvent | H33: Online classes/work / Cours ou travail en ligne | I33: Very Poor / TrÃ¨s mauvaise | J33: 3 | K33: Good / Stable | L33: Always / Toujours | M33: Slow internet / Internet lent | N33: Very often / TrÃ¨s souvent | O33: Night / Nuit | P33: School/Work / Ã‰cole/Travail | Q33: Moderate / Moyen | R33: Severely / Beaucoup | S33: Yes / Oui | T33: Yes / Oui | U33: Once a day / Une fois par jour | V33: Yes / Oui | W33: Battery usage / Batterie;Data usage / Consommation de donnÃ©es | X33: Battery usage / Batterie;Data usage / Consommation de donnÃ©es
A34: 2026/04/24 8:55:12 AM GMT+1 | B34: nahfrancis64@gmail.com | C34: MTN;Camtel | D34: Center Regional | E34: Android | F34: 20-25 | G34: Very often / TrÃ¨s souvent | H34: Social media / RÃ©seaux sociaux;Messaging / Messagerie (WhatsApp, etc.);Online classes/work / Cours ou travail en ligne;Programming | I34: Poor / Mauvaise | J34: 3 | K34: Poor / Instable | L34: Often / Souvent | M34: Slow internet / Internet lent;No signal / Pas de rÃ©seau | N34: Very often / TrÃ¨s souvent | O34: Morning / Matin | P34: School/Work / Ã‰cole/Travail | Q34: Weak / Faible | R34: Severely / Beaucoup | S34: Yes / Oui | T34: No / Non | U34: Only when there is a problem / Seulement en cas de problÃ¨me | V34: Yes / Oui | W34: Privacy / ConfidentialitÃ©;Data usage / Consommation de donnÃ©es;Security / SÃ©curitÃ© | X34: Privacy / ConfidentialitÃ©;Battery usage / Batterie;Data usage / Consommation de donnÃ©es
A35: 2026/04/24 8:55:58 AM GMT+1 | B35: tekweolivia@gmail.com | C35: MTN;Orange | D35: Southwest Region | E35: Android | F35: 25 and above | G35: Very often / TrÃ¨s souvent | H35: Social media / RÃ©seaux sociaux;Video streaming / VidÃ©o (YouTube, Netflix);Messaging / Messagerie (WhatsApp, etc.);Online classes/work / Cours ou travail en ligne;Browsing / Navigation | I35: Good / Bonne | J35: 3 | K35: Average / Moyenne | L35: Sometimes / Parfois | M35: Slow internet / Internet lent | N35: Sometimes / Parfois | O35: Afternoon / AprÃ¨s-midi | P35: Everywhere / Partout | Q35: Moderate / Moyen | R35: Moderately / Moyennement | S35: Yes / Oui | T35: Yes / Oui | U35: Once a day / Une fois par jour | V35: Yes / Oui | W35: Security / SÃ©curitÃ© | X35: Battery usage / Batterie
A36: 2026/04/24 8:59:45 AM GMT+1 | B36: gemuhakury@gmail.com | C36: MTN | D36: Southwest Region | E36: Android | F36: 20-25 | G36: Very often / TrÃ¨s souvent | H36: Social media / RÃ©seaux sociaux;Video streaming / VidÃ©o (YouTube, Netflix);Messaging / Messagerie (WhatsApp, etc.) | I36: Average / Moyenne | J36: 3 | K36: Poor / Instable | L36: Often / Souvent | M36: Slow internet / Internet lent;Poor call quality / Mauvaise qualitÃ© dâ€™appel | N36: Often / Souvent;Sometimes / Parfois | O36: Afternoon / AprÃ¨s-midi | P36: School/Work / Ã‰cole/Travail | Q36: Moderate / Moyen | R36: Severely / Beaucoup | S36: Yes / Oui | T36: Yes / Oui | U36: Once a day / Une fois par jour;Only when there is a problem / Seulement en cas de problÃ¨me | V36: Yes / Oui | W36: Privacy / ConfidentialitÃ©;Security / SÃ©curitÃ© | X36: Privacy / ConfidentialitÃ©;Data usage / Consommation de donnÃ©es;Security / SÃ©curitÃ©
A37: 2026/04/24 9:07:13 AM GMT+1 | B37: edelqueenmankaa@gmail.com | C37: MTN;Orange | D37: North West Region | E37: Android | F37: 20-25 | G37: Very often / TrÃ¨s souvent | H37: Social media / RÃ©seaux sociaux;Messaging / Messagerie (WhatsApp, etc.);Online classes/work / Cours ou travail en ligne | I37: Poor / Mauvaise;Average / Moyenne | J37: 3 | K37: Average / Moyenne | L37: Often / Souvent | M37: Slow internet / Internet lent;No signal / Pas de rÃ©seau;Poor call quality / Mauvaise qualitÃ© dâ€™appel | N37: Often / Souvent | O37: Afternoon / AprÃ¨s-midi | P37: School/Work / Ã‰cole/Travail | Q37: Moderate / Moyen | R37: Severely / Beaucoup | S37: Yes / Oui | T37: Yes / Oui | U37: Once a day / Une fois par jour | V37: Yes / Oui | W37: Privacy / ConfidentialitÃ©;Battery usage / Batterie;Data usage / Consommation de donnÃ©es;Security / SÃ©curitÃ© | X37: Privacy / ConfidentialitÃ©;Battery usage / Batterie;Data usage / Consommation de donnÃ©es;Security / SÃ©curitÃ©
... A64: 2026/04/24 10:23:56 AM GMT+1 | B64: njodzekareela@gmail.com | C64: MTN | D64: Southwest Region | E64: Android | F64: 20-25 | G64: Very often / TrÃ¨s souvent | H64: Social media / RÃ©seaux sociaux | I64: Average / Moyenne | J64: 3 | K64: Poor / Instable | L64: Sometimes / Parfois | M64: Slow internet / Internet lent | N64: Sometimes / Parfois | O64: Evening / Soir | P64: School/Work / Ã‰cole/Travail | Q64: Moderate / Moyen | R64: Moderately / Moyennement | S64: Yes / Oui | T64: Yes / Oui | U64: Only when there is a problem / Seulement en cas de problÃ¨me | V64: Yes / Oui | W64: Data usage / Consommation de donnÃ©es | X64: Data usage / Consommation de donnÃ©es
A65: 2026/04/24 10:29:35 AM GMT+1 | B65: w31449331@gmail.com | C65: Orange | D65: Littoral Region | E65: iPhone | F65: 20-25 | G65: Very often / TrÃ¨s souvent | H65: Social media / RÃ©seaux sociaux | I65: Good / Bonne | J65: 4 | K65: Good / Stable | L65: Sometimes / Parfois | M65: Network outages / Pannes rÃ©seau | N65: Sometimes / Parfois | O65: Evening / Soir | P65: School/Work / Ã‰cole/Travail | Q65: Strong / Fort | R65: Slightly / Un peu | S65: No / Non | T65: No / Non | U65: Never / Jamais | V65: No / Non | W65: Data usage / Consommation de donnÃ©es
A66: 2026/04/24 10:50:44 AM GMT+1 | B66: orchellenanfack049@gmail.com | C66: Camtel | D66: Southwest Region | E66: Android | F66: 15-20 | G66: Very often / TrÃ¨s souvent | H66: Online classes/work / Cours ou travail en ligne; | I66: Very Poor / TrÃ¨s mauvaise;Poor / Mauvaise | J66: 2 | K66: Poor / Instable | L66: Sometimes / Parfois | M66: Call drops / Coupures d'appel;No signal / Pas de rÃ©seau;Poor call quality / Mauvaise qualitÃ© dâ€™appel | N66: Often / Souvent | O66: Morning / Matin | P66: Everywhere / Partout | Q66: Moderate / Moyen | R66: Severely / Beaucoup | S66: Yes / Oui | T66: Yes / Oui | U66: Only when there is a problem / Seulement en cas de problÃ¨me | V66: Yes / Oui | W66: Data usage / Consommation de donnÃ©es
A67: 2026/04/24 10:53:26 AM GMT+1 | B67: tobeypaul3@gmail.com | C67: MTN;Orange | D67: Southwest Region | E67: Android | F67: 25 and above | G67: Very often / TrÃ¨s souvent | H67: Social media / RÃ©seaux sociaux;Video streaming / VidÃ©o (YouTube, Netflix);Messaging / Messagerie (WhatsApp, etc.);Online classes/work / Cours ou travail en ligne;Browsing / Navigation | I67: Average / Moyenne | J67: 3 | K67: Poor / Instable | L67: Sometimes / Parfois | M67: Poor call quality / Mauvaise qualitÃ© dâ€™appel | N67: Often / Souvent | O67: Afternoon / AprÃ¨s-midi | P67: Everywhere / Partout | Q67: Moderate / Moyen | R67: Severely / Beaucoup | S67: Yes / Oui | T67: Yes / Oui | U67: Once a day / Une fois par jour | V67: Yes / Oui | W67: Privacy / ConfidentialitÃ©;Battery usage / Batterie;Data usage / Consommation de donnÃ©es;Security / SÃ©curitÃ©
A68: 2026/04/24 10:59:37 AM GMT+1 | B68: favourfowfief@gmail.com | C68: MTN | D68: Southwest Region | E68: iPhone | F68: 20-25 | G68: Very often / TrÃ¨s souvent | H68: Social media / RÃ©seaux sociaux;Video streaming / VidÃ©o (YouTube, Netflix);Messaging / Messagerie (WhatsApp, etc.);Online classes/work / Cours ou travail en ligne;Gaming / Jeux;Browsing / Navigation | I68: Poor / Mauvaise | J68: 2 | K68: Very Poor / TrÃ¨s instable | L68: Often / Souvent | M68: Slow internet / Internet lent | N68: Often / Souvent | O68: Evening / Soir | P68: Everywhere / Partout | Q68: Weak / Faible | R68: Severely / Beaucoup | S68: Yes / Oui | T68: Yes / Oui | U68: Only when there is a problem / Seulement en cas de problÃ¨me | V68: No / Non | W68: Privacy / ConfidentialitÃ©;Battery usage / Batterie;Data usage / Consommation de donnÃ©es;Security / SÃ©curitÃ©
A69: 2026/04/24 11:02:58 AM GMT+1 | B69: nfamalando@gmail.com | C69: MTN | D69: Littoral Region | E69: Android | F69: 25 and above | G69: Very often / TrÃ¨s souvent | H69: Social media / RÃ©seaux sociaux;Video streaming / VidÃ©o (YouTube, Netflix);Messaging / Messagerie (WhatsApp, etc.);Online classes/work / Cours ou travail en ligne;Gaming / Jeux;Browsing / Navigation | I69: Average / Moyenne | J69: 3 | K69: Average / Moyenne | L69: Sometimes / Parfois | M69: Slow internet / Internet lent;Poor call quality / Mauvaise qualitÃ© dâ€™appel;Network outages / Pannes rÃ©seau | N69: Sometimes / Parfois | O69: Night / Nuit | P69: Everywhere / Partout | Q69: Moderate / Moyen | R69: Moderately / Moyennement | S69: No / Non | T69: Yes / Oui | U69: Only when there is a problem / Seulement en cas de problÃ¨me | V69: Yes / Oui | W69: Privacy / ConfidentialitÃ©;Battery usage / Batterie;Data usage / Consommation de donnÃ©es;Security / SÃ©curitÃ©
A70: 2026/04/24 11:03:58 AM GMT+1 | B70: chahkeziah@gmail.com | C70: MTN | D70: Southwest Region | E70: iPhone | F70: 20-25 | G70: Very often / TrÃ¨s souvent | H70: Social media / RÃ©seaux sociaux | I70: Average / Moyenne | J70: 2 | K70: Poor / Instable | L70: Sometimes / Parfois | M70: Slow internet / Internet lent | N70: Often / Souvent | O70: Evening / Soir | P70: School/Work / Ã‰cole/Travail | Q70: Moderate / Moyen | R70: Moderately / Moyennement | S70: Yes / Oui | U70: Only when there is a problem / Seulement en cas de problÃ¨me | V70: No / Non | W70: Data usage / Consommation de donnÃ©es
A71: 2026/04/24 11:04:40 AM GMT+1 | B71: davidharry870dh3819725@gmail.com | C71: MTN;Orange;Camtel | D71: Littoral Region | E71: Android;iPhone | F71: 20-25 | G71: Very often / TrÃ¨s souvent | H71: Social media / RÃ©seaux sociaux;Video streaming / VidÃ©o (YouTube, Netflix);Messaging / Messagerie (WhatsApp, etc.);Online classes/work / Cours ou travail en ligne;Gaming / Jeux;Browsing / Navigation | I71: Average / Moyenne;Good / Bonne | J71: 3 | K71: Good / Stable | L71: Rarely / Rarement | M71: Slow internet / Internet lent | N71: Rarely / Rarement | O71: Evening / Soir | P71: School/Work / Ã‰cole/Travail | Q71: Moderate / Moyen | R71: Severely / Beaucoup | S71: Yes / Oui | T71: No / Non | U71: Once a day / Une fois par jour | V71: Yes / Oui | W71: Privacy / ConfidentialitÃ©
...

Sheet Clean_Data
A1: Timestamp | B1: Respondent | C1: Network Provider | D1: Region | E1: Phone Type | F1: Age Range | G1: Internet Usage Frequency | H1: Main Data Usage | I1: Overall Experience | J1: Internet Speed (1-5) | K1: Connection Reliability | L1: Video Buffering Frequency | M1: Main Problem | N1: Problem Frequency | O1: Worst Network Time | P1: Problem Location | Q1: Signal Strength | R1: Impact on Daily Activities | S1: Would Use App | T1: Allow Auto Collection | U1: Feedback Frequency | V1: Comfortable Sharing Location | W1: App Concerns
A2: =Raw_Data!A2 -> 2026/04/23 10:31:16 PM GMT+1 | B2: =Raw_Data!B2 -> yasiritemwa233@gmail.com | C2: =IFERROR(textbefore(Raw_Data!C2," / "),Raw_Data!C2) -> Orange | D2: =IFERROR(textbefore(Raw_Data!D2," / "),Raw_Data!D2) -> Southwest Region | E2: =IFERROR(textbefore(Raw_Data!E2," / "),Raw_Data!E2) -> Android | F2: =IFERROR(textbefore(Raw_Data!F2," / "),Raw_Data!F2) -> 20-25 | G2: =IFERROR(textbefore(textbefore(Raw_Data!G2,";")," / "),IFERROR(textbefore(Raw_Data!G2," / "),Raw_Data!G2)) -> Very often / TrÃ¨s souvent | H2: =IFERROR(textbefore(Raw_Data!H2," / "),Raw_Data!H2) -> Browsing / Navigation | I2: =IFERROR(textbefore(Raw_Data!I2," / "),Raw_Data!I2) -> Poor / Mauvaise | J2: =Raw_Data!J2 -> 2 | K2: =IFERROR(textbefore(Raw_Data!K2," / "),Raw_Data!K2) -> Poor / Instable | L2: =IFERROR(textbefore(Raw_Data!L2," / "),Raw_Data!L2) -> Often / Souvent | M2: =IFERROR(textbefore(Raw_Data!M2," / "),Raw_Data!M2) -> Slow internet / Internet lent | N2: =IFERROR(textbefore(Raw_Data!N2," / "),Raw_Data!N2) -> Often / Souvent | O2: =IFERROR(textbefore(Raw_Data!O2," / "),Raw_Data!O2) -> Night / Nuit | P2: =IFERROR(textbefore(Raw_Data!P2," / "),Raw_Data!P2) -> Everywhere / Partout | Q2: =IFERROR(textbefore(Raw_Data!Q2," / "),Raw_Data!Q2) -> Weak / Faible | R2: =IFERROR(textbefore(Raw_Data!R2," / "),Raw_Data!R2) -> Severely / Beaucoup | ... W2: =IFERROR(textbefore(Raw_Data!W2," / "),Raw_Data!W2) -> Battery usage / Batterie;Data usage / Consommation de donnÃ©es;Security / SÃ©curitÃ©
A3: =Raw_Data!A3 -> 2026/04/23 10:54:23 PM GMT+1 | B3: =Raw_Data!B3 -> maagboramelia123@gmail.com | C3: =IFERROR(textbefore(Raw_Data!C3," / "),Raw_Data!C3) -> MTN | D3: =IFERROR(textbefore(Raw_Data!D3," / "),Raw_Data!D3) -> Southwest Region | E3: =IFERROR(textbefore(Raw_Data!E3," / "),Raw_Data!E3) -> Android | F3: =IFERROR(textbefore(Raw_Data!F3," / "),Raw_Data!F3) -> 20-25 | G3: =IFERROR(textbefore(textbefore(Raw_Data!G3,";")," / "),IFERROR(textbefore(Raw_Data!G3," / "),Raw_Data!G3)) -> Very often / TrÃ¨s souvent | H3: =IFERROR(textbefore(Raw_Data!H3," / "),Raw_Data!H3) -> Social media / RÃ©seaux sociaux | I3: =IFERROR(textbefore(Raw_Data!I3," / "),Raw_Data!I3) -> Very Poor / TrÃ¨s mauvaise | J3: =Raw_Data!J3 -> 3 | K3: =IFERROR(textbefore(Raw_Data!K3," / "),Raw_Data!K3) -> Very Poor / TrÃ¨s instable | L3: =IFERROR(textbefore(Raw_Data!L3," / "),Raw_Data!L3) -> Often / Souvent | M3: =IFERROR(textbefore(Raw_Data!M3," / "),Raw_Data!M3) -> Slow internet / Internet lent | N3: =IFERROR(textbefore(Raw_Data!N3," / "),Raw_Data!N3) -> Very often / TrÃ¨s souvent | O3: =IFERROR(textbefore(Raw_Data!O3," / "),Raw_Data!O3) -> Night / Nuit | P3: =IFERROR(textbefore(Raw_Data!P3," / "),Raw_Data!P3) -> Everywhere / Partout | Q3: =IFERROR(textbefore(Raw_Data!Q3," / "),Raw_Data!Q3) -> Moderate / Moyen | R3: =IFERROR(textbefore(Raw_Data!R3," / "),Raw_Data!R3) -> Severely / Beaucoup | ... W3: =IFERROR(textbefore(Raw_Data!W3," / "),Raw_Data!W3) -> Privacy / ConfidentialitÃ©;Battery usage / Batterie;Security / SÃ©curitÃ©
A4: =Raw_Data!A4 -> 2026/04/23 11:07:04 PM GMT+1 | B4: =Raw_Data!B4 -> yvettecrystal24@gmail.com | C4: =IFERROR(textbefore(Raw_Data!C4," / "),Raw_Data!C4) -> MTN;Orange | D4: =IFERROR(textbefore(Raw_Data!D4," / "),Raw_Data!D4) -> North West Region | E4: =IFERROR(textbefore(Raw_Data!E4," / "),Raw_Data!E4) -> iPhone | F4: =IFERROR(textbefore(Raw_Data!F4," / "),Raw_Data!F4) -> 20-25 | G4: =IFERROR(textbefore(textbefore(Raw_Data!G4,";")," / "),IFERROR(textbefore(Raw_Data!G4," / "),Raw_Data!G4)) -> Very often / TrÃ¨s souvent | H4: =IFERROR(textbefore(Raw_Data!H4," / "),Raw_Data!H4) -> Social media / RÃ©seaux sociaux;Messaging / Messagerie (WhatsApp, etc.);Online classes/work / Cours ou travail en ligne;Gaming / Jeux;Browsing / Navigation | I4: =IFERROR(textbefore(Raw_Data!I4," / "),Raw_Data!I4) -> Average / Moyenne | J4: =Raw_Data!J4 -> 3 | K4: =IFERROR(textbefore(Raw_Data!K4," / "),Raw_Data!K4) -> Average / Moyenne | L4: =IFERROR(textbefore(Raw_Data!L4," / "),Raw_Data!L4) -> Sometimes / Parfois | M4: =IFERROR(textbefore(Raw_Data!M4," / "),Raw_Data!M4) -> Slow internet / Internet lent;No signal / Pas de rÃ©seau | N4: =IFERROR(textbefore(Raw_Data!N4," / "),Raw_Data!N4) -> Often / Souvent | O4: =IFERROR(textbefore(Raw_Data!O4," / "),Raw_Data!O4) -> Afternoon / AprÃ¨s-midi | P4: =IFERROR(textbefore(Raw_Data!P4," / "),Raw_Data!P4) -> Everywhere / Partout | Q4: =IFERROR(textbefore(Raw_Data!Q4," / "),Raw_Data!Q4) -> Moderate / Moyen | R4: =IFERROR(textbefore(Raw_Data!R4," / "),Raw_Data!R4) -> Moderately / Moyennement | ... W4: =IFERROR(textbefore(Raw_Data!W4," / "),Raw_Data!W4) -> Privacy / ConfidentialitÃ©;Data usage / Consommation de donnÃ©es;Security / SÃ©curitÃ©
A5: =Raw_Data!A5 -> 2026/04/23 11:18:50 PM GMT+1 | B5: =Raw_Data!B5 -> bjuclear@gmail.com | C5: =IFERROR(textbefore(Raw_Data!C5," / "),Raw_Data!C5) -> MTN | D5: =IFERROR(textbefore(Raw_Data!D5," / "),Raw_Data!D5) -> Southwest Region | E5: =IFERROR(textbefore(Raw_Data!E5," / "),Raw_Data!E5) -> Android | F5: =IFERROR(textbefore(Raw_Data!F5," / "),Raw_Data!F5) -> 20-25 | G5: =IFERROR(textbefore(textbefore(Raw_Data!G5,";")," / "),IFERROR(textbefore(Raw_Data!G5," / "),Raw_Data!G5)) -> Very often / TrÃ¨s souvent | H5: =IFERROR(textbefore(Raw_Data!H5," / "),Raw_Data!H5) -> Social media / RÃ©seaux sociaux | I5: =IFERROR(textbefore(Raw_Data!I5," / "),Raw_Data!I5) -> Poor / Mauvaise;Average / Moyenne | J5: =Raw_Data!J5 -> 3 | K5: =IFERROR(textbefore(Raw_Data!K5," / "),Raw_Data!K5) -> Average / Moyenne | L5: =IFERROR(textbefore(Raw_Data!L5," / "),Raw_Data!L5) -> Sometimes / Parfois | M5: =IFERROR(textbefore(Raw_Data!M5," / "),Raw_Data!M5) -> Slow internet / Internet lent | N5: =IFERROR(textbefore(Raw_Data!N5," / "),Raw_Data!N5) -> Often / Souvent | O5: =IFERROR(textbefore(Raw_Data!O5," / "),Raw_Data!O5) -> Evening / Soir | P5: =IFERROR(textbefore(Raw_Data!P5," / "),Raw_Data!P5) -> School/Work / Ã‰cole/Travail | Q5: =IFERROR(textbefore(Raw_Data!Q5," / "),Raw_Data!Q5) -> Moderate / Moyen | R5: =IFERROR(textbefore(Raw_Data!R5," / "),Raw_Data!R5) -> Severely / Beaucoup | ... W5: =IFERROR(textbefore(Raw_Data!W5," / "),Raw_Data!W5) -> Privacy / ConfidentialitÃ©;Battery usage / Batterie;Data usage / Consommation de donnÃ©es;Security / SÃ©curitÃ©
A6: =Raw_Data!A6 -> 2026/04/23 11:25:07 PM GMT+1 | B6: =Raw_Data!B6 -> fulopila9@gmail.com | C6: =IFERROR(textbefore(Raw_Data!C6," / "),Raw_Data!C6) -> MTN;Orange;Camtel | D6: =IFERROR(textbefore(Raw_Data!D6," / "),Raw_Data!D6) -> Southwest Region | E6: =IFERROR(textbefore(Raw_Data!E6," / "),Raw_Data!E6) -> Android;iPhone | F6: =IFERROR(textbefore(Raw_Data!F6," / "),Raw_Data!F6) -> 25 and above | G6: =IFERROR(textbefore(textbefore(Raw_Data!G6,";")," / "),IFERROR(textbefore(Raw_Data!G6," / "),Raw_Data!G6)) -> Very often / TrÃ¨s souvent | H6: =IFERROR(textbefore(Raw_Data!H6," / "),Raw_Data!H6) -> Social media / RÃ©seaux sociaux;Messaging / Messagerie (WhatsApp, etc.);Browsing / Navigation;Software development | I6: =IFERROR(textbefore(Raw_Data!I6," / "),Raw_Data!I6) -> Average / Moyenne | J6: =Raw_Data!J6 -> 2 | K6: =IFERROR(textbefore(Raw_Data!K6," / "),Raw_Data!K6) -> Poor / Instable | L6: =IFERROR(textbefore(Raw_Data!L6," / "),Raw_Data!L6) -> Often / Souvent | M6: =IFERROR(textbefore(Raw_Data!M6," / "),Raw_Data!M6) -> Slow internet / Internet lent;Call drops / Coupures d'appel;No signal / Pas de rÃ©seau;Poor call quality / Mauvaise qualitÃ© dâ€™appel;Network outages / Pannes rÃ©seau | N6: =IFERROR(textbefore(Raw_Data!N6," / "),Raw_Data!N6) -> Often / Souvent | O6: =IFERROR(textbefore(Raw_Data!O6," / "),Raw_Data!O6) -> Afternoon / AprÃ¨s-midi | P6: =IFERROR(textbefore(Raw_Data!P6," / "),Raw_Data!P6) -> Everywhere / Partout | Q6: =IFERROR(textbefore(Raw_Data!Q6," / "),Raw_Data!Q6) -> Moderate / Moyen | R6: =IFERROR(textbefore(Raw_Data!R6," / "),Raw_Data!R6) -> Severely / Beaucoup | ... W6: =IFERROR(textbefore(Raw_Data!W6," / "),Raw_Data!W6) -> Privacy / ConfidentialitÃ©;Data usage / Consommation de donnÃ©es;Security / SÃ©curitÃ©
A7: =Raw_Data!A7 -> 2026/04/23 11:25:43 PM GMT+1 | B7: =Raw_Data!B7 -> tafopaabigail11@gmail.com | C7: =IFERROR(textbefore(Raw_Data!C7," / "),Raw_Data!C7) -> MTN | D7: =IFERROR(textbefore(Raw_Data!D7," / "),Raw_Data!D7) -> Center Regional | E7: =IFERROR(textbefore(Raw_Data!E7," / "),Raw_Data!E7) -> Android | F7: =IFERROR(textbefore(Raw_Data!F7," / "),Raw_Data!F7) -> 15-20 | G7: =IFERROR(textbefore(textbefore(Raw_Data!G7,";")," / "),IFERROR(textbefore(Raw_Data!G7," / "),Raw_Data!G7)) -> Very often / TrÃ¨s souvent | H7: =IFERROR(textbefore(Raw_Data!H7," / "),Raw_Data!H7) -> Social media / RÃ©seaux sociaux;Online classes/work / Cours ou travail en ligne | I7: =IFERROR(textbefore(Raw_Data!I7," / "),Raw_Data!I7) -> Average / Moyenne | J7: =Raw_Data!J7 -> 2 | K7: =IFERROR(textbefore(Raw_Data!K7," / "),Raw_Data!K7) -> Average / Moyenne | L7: =IFERROR(textbefore(Raw_Data!L7," / "),Raw_Data!L7) -> Always / Toujours | M7: =IFERROR(textbefore(Raw_Data!M7," / "),Raw_Data!M7) -> Slow internet / Internet lent;No signal / Pas de rÃ©seau;Network outages / Pannes rÃ©seau | N7: =IFERROR(textbefore(Raw_Data!N7," / "),Raw_Data!N7) -> Very often / TrÃ¨s souvent | O7: =IFERROR(textbefore(Raw_Data!O7," / "),Raw_Data!O7) -> Afternoon / AprÃ¨s-midi | P7: =IFERROR(textbefore(Raw_Data!P7," / "),Raw_Data!P7) -> School/Work / Ã‰cole/Travail | Q7: =IFERROR(textbefore(Raw_Data!Q7," / "),Raw_Data!Q7) -> Strong / Fort | R7: =IFERROR(textbefore(Raw_Data!R7," / "),Raw_Data!R7) -> Severely / Beaucoup | ... W7: =IFERROR(textbefore(Raw_Data!W7," / "),Raw_Data!W7) -> Privacy / ConfidentialitÃ©;Security / SÃ©curitÃ©
A8: =Raw_Data!A8 -> 2026/04/23 11:26:31 PM GMT+1 | B8: =Raw_Data!B8 -> nkengafac.madelene.olive@gmail.com | C8: =IFERROR(textbefore(Raw_Data!C8," / "),Raw_Data!C8) -> MTN | D8: =IFERROR(textbefore(Raw_Data!D8," / "),Raw_Data!D8) -> Southwest Region | E8: =IFERROR(textbefore(Raw_Data!E8," / "),Raw_Data!E8) -> Android | F8: =IFERROR(textbefore(Raw_Data!F8," / "),Raw_Data!F8) -> 20-25 | G8: =IFERROR(textbefore(textbefore(Raw_Data!G8,";")," / "),IFERROR(textbefore(Raw_Data!G8," / "),Raw_Data!G8)) -> Often / Souvent | H8: =IFERROR(textbefore(Raw_Data!H8," / "),Raw_Data!H8) -> Messaging / Messagerie (WhatsApp, etc.);Browsing / Navigation | I8: =IFERROR(textbefore(Raw_Data!I8," / "),Raw_Data!I8) -> Poor / Mauvaise | J8: =Raw_Data!J8 -> 1 | K8: =IFERROR(textbefore(Raw_Data!K8," / "),Raw_Data!K8) -> Poor / Instable | L8: =IFERROR(textbefore(Raw_Data!L8," / "),Raw_Data!L8) -> Always / Toujours | M8: =IFERROR(textbefore(Raw_Data!M8," / "),Raw_Data!M8) -> Slow internet / Internet lent;Call drops / Coupures d'appel;No signal / Pas de rÃ©seau;Poor call quality / Mauvaise qualitÃ© dâ€™appel | N8: =IFERROR(textbefore(Raw_Data!N8," / "),Raw_Data!N8) -> Often / Souvent | O8: =IFERROR(textbefore(Raw_Data!O8," / "),Raw_Data!O8) -> Afternoon / AprÃ¨s-midi | P8: =IFERROR(textbefore(Raw_Data!P8," / "),Raw_Data!P8) -> School/Work / Ã‰cole/Travail | Q8: =IFERROR(textbefore(Raw_Data!Q8," / "),Raw_Data!Q8) -> Weak / Faible | R8: =IFERROR(textbefore(Raw_Data!R8," / "),Raw_Data!R8) -> Severely / Beaucoup | ... W8: =IFERROR(textbefore(Raw_Data!W8," / "),Raw_Data!W8) -> Privacy / ConfidentialitÃ©;Security / SÃ©curitÃ©
A9: =Raw_Data!A9 -> 2026/04/23 11:34:00 PM GMT+1 | B9: =Raw_Data!B9 -> emmanugwe31@gmail.com | C9: =IFERROR(textbefore(Raw_Data!C9," / "),Raw_Data!C9) -> MTN;Orange;Camtel | D9: =IFERROR(textbefore(Raw_Data!D9," / "),Raw_Data!D9) -> North West Region | E9: =IFERROR(textbefore(Raw_Data!E9," / "),Raw_Data!E9) -> Android | F9: =IFERROR(textbefore(Raw_Data!F9," / "),Raw_Data!F9) -> 20-25 | G9: =IFERROR(textbefore(textbefore(Raw_Data!G9,";")," / "),IFERROR(textbefore(Raw_Data!G9," / "),Raw_Data!G9)) -> Very often / TrÃ¨s souvent | H9: =IFERROR(textbefore(Raw_Data!H9," / "),Raw_Data!H9) -> Social media / RÃ©seaux sociaux;Messaging / Messagerie (WhatsApp, etc.);Online classes/work / Cours ou travail en ligne;Browsing / Navigation;Do surveys to help improve network | I9: =IFERROR(textbefore(Raw_Data!I9," / "),Raw_Data!I9) -> Average / Moyenne | J9: =Raw_Data!J9 -> 3 | K9: =IFERROR(textbefore(Raw_Data!K9," / "),Raw_Data!K9) -> Average / Moyenne | L9: =IFERROR(textbefore(Raw_Data!L9," / "),Raw_Data!L9) -> Sometimes / Parfois | M9: =IFERROR(textbefore(Raw_Data!M9," / "),Raw_Data!M9) -> Slow internet / Internet lent;Network outages / Pannes rÃ©seau | N9: =IFERROR(textbefore(Raw_Data!N9," / "),Raw_Data!N9) -> Often / Souvent | O9: =IFERROR(textbefore(Raw_Data!O9," / "),Raw_Data!O9) -> Afternoon / AprÃ¨s-midi | P9: =IFERROR(textbefore(Raw_Data!P9," / "),Raw_Data!P9) -> Everywhere / Partout | Q9: =IFERROR(textbefore(Raw_Data!Q9," / "),Raw_Data!Q9) -> Moderate / Moyen | R9: =IFERROR(textbefore(Raw_Data!R9," / "),Raw_Data!R9) -> Moderately / Moyennement | ... W9: =IFERROR(textbefore(Raw_Data!W9," / "),Raw_Data!W9) -> Privacy / ConfidentialitÃ©
A10: =Raw_Data!A10 -> 2026/04/24 12:49:27 AM GMT+1 | B10: =Raw_Data!B10 -> cristianoace224@gmail.com | C10: =IFERROR(textbefore(Raw_Data!C10," / "),Raw_Data!C10) -> MTN;Orange | D10: =IFERROR(textbefore(Raw_Data!D10," / "),Raw_Data!D10) -> North Region | E10: =IFERROR(textbefore(Raw_Data!E10," / "),Raw_Data!E10) -> Android | F10: =IFERROR(textbefore(Raw_Data!F10," / "),Raw_Data!F10) -> 25 and above | G10: =IFERROR(textbefore(textbefore(Raw_Data!G10,";")," / "),IFERROR(textbefore(Raw_Data!G10," / "),Raw_Data!G10)) -> Very often / TrÃ¨s souvent | H10: =IFERROR(textbefore(Raw_Data!H10," / "),Raw_Data!H10) -> Social media / RÃ©seaux sociaux;Video streaming / VidÃ©o (YouTube, Netflix);Messaging / Messagerie (WhatsApp, etc.);Gaming / Jeux | I10: =IFERROR(textbefore(Raw_Data!I10," / "),Raw_Data!I10) -> Average / Moyenne | J10: =Raw_Data!J10 -> 3 | K10: =IFERROR(textbefore(Raw_Data!K10," / "),Raw_Data!K10) -> Average / Moyenne | L10: =IFERROR(textbefore(Raw_Data!L10," / "),Raw_Data!L10) -> Sometimes / Parfois | M10: =IFERROR(textbefore(Raw_Data!M10," / "),Raw_Data!M10) -> No signal / Pas de rÃ©seau | N10: =IFERROR(textbefore(Raw_Data!N10," / "),Raw_Data!N10) -> Sometimes / Parfois | O10: =IFERROR(textbefore(Raw_Data!O10," / "),Raw_Data!O10) -> Afternoon / AprÃ¨s-midi | P10: =IFERROR(textbefore(Raw_Data!P10," / "),Raw_Data!P10) -> Everywhere / Partout | Q10: =IFERROR(textbefore(Raw_Data!Q10," / "),Raw_Data!Q10) -> Moderate / Moyen | R10: =IFERROR(textbefore(Raw_Data!R10," / "),Raw_Data!R10) -> Severely / Beaucoup | ... W10: =IFERROR(textbefore(Raw_Data!W10," / "),Raw_Data!W10) -> None / Aucune
A11: =Raw_Data!A11 -> 2026/04/24 12:54:34 AM GMT+1 | B11: =Raw_Data!B11 -> isaiahafese@gmail.com | C11: =IFERROR(textbefore(Raw_Data!C11," / "),Raw_Data!C11) -> MTN | D11: =IFERROR(textbefore(Raw_Data!D11," / "),Raw_Data!D11) -> North West Region | E11: =IFERROR(textbefore(Raw_Data!E11," / "),Raw_Data!E11) -> iPhone | F11: =IFERROR(textbefore(Raw_Data!F11," / "),Raw_Data!F11) -> 15-20 | G11: =IFERROR(textbefore(textbefore(Raw_Data!G11,";")," / "),IFERROR(textbefore(Raw_Data!G11," / "),Raw_Data!G11)) -> Very often / TrÃ¨s souvent | H11: =IFERROR(textbefore(Raw_Data!H11," / "),Raw_Data!H11) -> Classified | I11: =IFERROR(textbefore(Raw_Data!I11," / "),Raw_Data!I11) -> Good / Bonne | J11: =Raw_Data!J11 -> 4 | K11: =IFERROR(textbefore(Raw_Data!K11," / "),Raw_Data!K11) -> Good / Stable | L11: =IFERROR(textbefore(Raw_Data!L11," / "),Raw_Data!L11) -> Never / Jamais | M11: =IFERROR(textbefore(Raw_Data!M11," / "),Raw_Data!M11) -> Slow internet / Internet lent | N11: =IFERROR(textbefore(Raw_Data!N11," / "),Raw_Data!N11) -> Sometimes / Parfois | O11: =IFERROR(textbefore(Raw_Data!O11," / "),Raw_Data!O11) -> Afternoon / AprÃ¨s-midi | P11: =IFERROR(textbefore(Raw_Data!P11," / "),Raw_Data!P11) -> School/Work / Ã‰cole/Travail | Q11: =IFERROR(textbefore(Raw_Data!Q11," / "),Raw_Data!Q11) -> Moderate / Moyen | R11: =IFERROR(textbefore(Raw_Data!R11," / "),Raw_Data!R11) -> Severely / Beaucoup | ... W11: =IFERROR(textbefore(Raw_Data!W11," / "),Raw_Data!W11) -> Privacy / ConfidentialitÃ©
A12: =Raw_Data!A12 -> 2026/04/24 1:01:49 AM GMT+1 | B12: =Raw_Data!B12 -> teyimdiane@gmail.com | C12: =IFERROR(textbefore(Raw_Data!C12," / "),Raw_Data!C12) -> MTN | D12: =IFERROR(textbefore(Raw_Data!D12," / "),Raw_Data!D12) -> Southwest Region | E12: =IFERROR(textbefore(Raw_Data!E12," / "),Raw_Data!E12) -> iPhone | F12: =IFERROR(textbefore(Raw_Data!F12," / "),Raw_Data!F12) -> 20-25 | G12: =IFERROR(textbefore(textbefore(Raw_Data!G12,";")," / "),IFERROR(textbefore(Raw_Data!G12," / "),Raw_Data!G12)) -> Very often / TrÃ¨s souvent | H12: =IFERROR(textbefore(Raw_Data!H12," / "),Raw_Data!H12) -> Social media / RÃ©seaux sociaux;Messaging / Messagerie (WhatsApp, etc.) | I12: =IFERROR(textbefore(Raw_Data!I12," / "),Raw_Data!I12) -> Poor / Mauvaise | J12: =Raw_Data!J12 -> 3 | K12: =IFERROR(textbefore(Raw_Data!K12," / "),Raw_Data!K12) -> Poor / Instable | L12: =IFERROR(textbefore(Raw_Data!L12," / "),Raw_Data!L12) -> Often / Souvent | M12: =IFERROR(textbefore(Raw_Data!M12," / "),Raw_Data!M12) -> Slow internet / Internet lent;No signal / Pas de rÃ©seau;Poor call quality / Mauvaise qualitÃ© dâ€™appel | N12: =IFERROR(textbefore(Raw_Data!N12," / "),Raw_Data!N12) -> Sometimes / Parfois | O12: =IFERROR(textbefore(Raw_Data!O12," / "),Raw_Data!O12) -> Afternoon / AprÃ¨s-midi | P12: =IFERROR(textbefore(Raw_Data!P12," / "),Raw_Data!P12) -> Everywhere / Partout | Q12: =IFERROR(textbefore(Raw_Data!Q12," / "),Raw_Data!Q12) -> Moderate / Moyen | R12: =IFERROR(textbefore(Raw_Data!R12," / "),Raw_Data!R12) -> Moderately / Moyennement | ... W12: =IFERROR(textbefore(Raw_Data!W12," / "),Raw_Data!W12) -> Privacy / ConfidentialitÃ©
A13: =Raw_Data!A13 -> 2026/04/24 1:44:54 AM GMT+1 | B13: =Raw_Data!B13 -> ndanjongdan@gmail.com | C13: =IFERROR(textbefore(Raw_Data!C13," / "),Raw_Data!C13) -> MTN | D13: =IFERROR(textbefore(Raw_Data!D13," / "),Raw_Data!D13) -> North West Region | E13: =IFERROR(textbefore(Raw_Data!E13," / "),Raw_Data!E13) -> Android | F13: =IFERROR(textbefore(Raw_Data!F13," / "),Raw_Data!F13) -> 20-25 | G13: =IFERROR(textbefore(textbefore(Raw_Data!G13,";")," / "),IFERROR(textbefore(Raw_Data!G13," / "),Raw_Data!G13)) -> Very often / TrÃ¨s souvent | H13: =IFERROR(textbefore(Raw_Data!H13," / "),Raw_Data!H13) -> Social media / RÃ©seaux sociaux;Messaging / Messagerie (WhatsApp, etc.);Online classes/work / Cours ou travail en ligne;Browsing / Navigation | I13: =IFERROR(textbefore(Raw_Data!I13," / "),Raw_Data!I13) -> Poor / Mauvaise | J13: =Raw_Data!J13 -> 2 | K13: =IFERROR(textbefore(Raw_Data!K13," / "),Raw_Data!K13) -> Average / Moyenne | L13: =IFERROR(textbefore(Raw_Data!L13," / "),Raw_Data!L13) -> Often / Souvent | M13: =IFERROR(textbefore(Raw_Data!M13," / "),Raw_Data!M13) -> Slow internet / Internet lent;Poor call quality / Mauvaise qualitÃ© dâ€™appel;Network outages / Pannes rÃ©seau | N13: =IFERROR(textbefore(Raw_Data!N13," / "),Raw_Data!N13) -> Often / Souvent | O13: =IFERROR(textbefore(Raw_Data!O13," / "),Raw_Data!O13) -> Afternoon / AprÃ¨s-midi | P13: =IFERROR(textbefore(Raw_Data!P13," / "),Raw_Data!P13) -> Everywhere / Partout | Q13: =IFERROR(textbefore(Raw_Data!Q13," / "),Raw_Data!Q13) -> Moderate / Moyen | R13: =IFERROR(textbefore(Raw_Data!R13," / "),Raw_Data!R13) -> Severely / Beaucoup | ... W13: =IFERROR(textbefore(Raw_Data!W13," / "),Raw_Data!W13) -> Privacy / ConfidentialitÃ©;Data usage / Consommation de donnÃ©es;Security / SÃ©curitÃ©
... A121: =Raw_Data!A121 -> 2026/04/25 9:38:01 PM GMT+1 | B121: =Raw_Data!B121 -> djieutcheuchantal@gmail.com | C121: =IFERROR(textbefore(Raw_Data!C121," / "),Raw_Data!C121) -> MTN;Orange | D121: =IFERROR(textbefore(Raw_Data!D121," / "),Raw_Data!D121) -> Southwest Region | E121: =IFERROR(textbefore(Raw_Data!E121," / "),Raw_Data!E121) -> Android | F121: =IFERROR(textbefore(Raw_Data!F121," / "),Raw_Data!F121) -> 20-25 | G121: =IFERROR(textbefore(textbefore(Raw_Data!G121,";")," / "),IFERROR(textbefore(Raw_Data!G121," / "),Raw_Data!G121)) -> Very often / TrÃ¨s souvent | H121: =IFERROR(textbefore(Raw_Data!H121," / "),Raw_Data!H121) -> Social media / RÃ©seaux sociaux;Video streaming / VidÃ©o (YouTube, Netflix);Messaging / Messagerie (WhatsApp, etc.);Browsing / Navigation | I121: =IFERROR(textbefore(Raw_Data!I121," / "),Raw_Data!I121) -> Average / Moyenne | J121: =Raw_Data!J121 -> 3 | K121: =IFERROR(textbefore(Raw_Data!K121," / "),Raw_Data!K121) -> Average / Moyenne | L121: =IFERROR(textbefore(Raw_Data!L121," / "),Raw_Data!L121) -> Sometimes / Parfois | M121: =IFERROR(textbefore(Raw_Data!M121," / "),Raw_Data!M121) -> Slow internet / Internet lent;No signal / Pas de rÃ©seau;Poor call quality / Mauvaise qualitÃ© dâ€™appel | N121: =IFERROR(textbefore(Raw_Data!N121," / "),Raw_Data!N121) -> Sometimes / Parfois | O121: =IFERROR(textbefore(Raw_Data!O121," / "),Raw_Data!O121) -> Evening / Soir | P121: =IFERROR(textbefore(Raw_Data!P121," / "),Raw_Data!P121) -> School/Work / Ã‰cole/Travail | Q121: =IFERROR(textbefore(Raw_Data!Q121," / "),Raw_Data!Q121) -> Moderate / Moyen | R121: =IFERROR(textbefore(Raw_Data!R121," / "),Raw_Data!R121) -> Slightly / Un peu | ... W121: =IFERROR(textbefore(Raw_Data!W121," / "),Raw_Data!W121) -> Privacy / ConfidentialitÃ©;Data usage / Consommation de donnÃ©es;Security / SÃ©curitÃ©

Sheet Processed_Data
A1: Timestamp | B1: Respondent | C1: Network Provider | D1: Region | E1: Phone Type | F1: Age Range | G1: Internet Usage Frequency | H1: Main Data Usage | I1: Overall Experience | J1: Internet Speed (1-5) | K1: Connection Reliability | L1: Video Buffering Frequency | M1: Main Problem | N1: Problem Frequency | O1: Worst Network Time | P1: Problem Location | Q1: Signal Strength | R1: Impact on Daily Activities | S1: Would Use App | T1: Allow Auto Collection | U1: Feedback Frequency | V1: Comfortable Sharing Location | W1: App Concerns
A2: 2026/04/23 10:31:16 PM GMT+1 | B2: User_1 | C2: Orange | D2: Southwest Region | E2: Android | F2: 20-25 | G2: Very often | H2: Browsing | I2: Poor | J2: 2 | K2: Poor | L2: Often | M2: Slow internet | N2: Often | O2: Night | P2: Everywhere | Q2: Weak | R2: Severely | S2: Yes | T2: Yes | U2: Once a day | V2: Yes | W2: Battery usage, Data usage, Security
A3: 2026/04/23 10:54:23 PM GMT+1 | B3: User_2 | C3: MTN | D3: Southwest Region | E3: Android | F3: 20-25 | G3: Very often | H3: Social media | I3: Very Poor | J3: 3 | K3: Very Poor | L3: Often | M3: Slow internet | N3: Very often | O3: Night | P3: Everywhere | Q3: Moderate | R3: Severely | S3: No | T3: No | U3: Never | V3: No | W3: Privacy, Battery usage, Security
A4: 2026/04/23 11:07:04 PM GMT+1 | B4: User_3 | C4: MTN, Orange | D4: North West Region | E4: iPhone | F4: 20-25 | G4: Very often | H4: Social media, Messaging, Online classes/work, Gaming, Browsing | I4: Average | J4: 3 | K4: Average | L4: Sometimes | M4: Slow internet, No signal | N4: Often | O4: Afternoon | P4: Everywhere | Q4: Moderate | R4: Moderately | S4: Yes | T4: Yes | U4: Once a day | V4: Yes | W4: Privacy, Data usage, Security
A5: 2026/04/23 11:18:50 PM GMT+1 | B5: User_4 | C5: MTN | D5: Southwest Region | E5: Android | F5: 20-25 | G5: Very often | H5: Social media | I5: Poor | J5: 3 | K5: Average | L5: Sometimes | M5: Slow internet | N5: Often | O5: Evening | P5: School/Work | Q5: Moderate | R5: Severely | S5: Yes | T5: Yes | U5: Only when there is a problem | V5: Yes | W5: Privacy, Battery usage, Data usage, Security
A6: 2026/04/23 11:25:07 PM GMT+1 | B6: User_5 | C6: MTN, Orange, Camtel | D6: Southwest Region | E6: Android, iPhone | F6: 25 and above | G6: Very often | H6: Social media, Messaging, Browsing, Software development | I6: Average | J6: 2 | K6: Poor | L6: Often | M6: Slow internet, Call drops, No signal, Poor call quality, Network outages | N6: Often | O6: Afternoon | P6: Everywhere | Q6: Moderate | R6: Severely | S6: Yes | T6: Yes | U6: Only when there is a problem | V6: Yes | W6: Privacy, Data usage, Security
A7: 2026/04/23 11:25:43 PM GMT+1 | B7: User_6 | C7: MTN | D7: Center Regional | E7: Android | F7: 15-20 | G7: Very often | H7: Social media, Online classes/work | I7: Average | J7: 2 | K7: Average | L7: Always | M7: Slow internet, No signal, Network outages | N7: Very often | O7: Afternoon | P7: School/Work | Q7: Strong | R7: Severely | S7: Yes | T7: No | U7: Only when there is a problem | V7: No | W7: Privacy, Security
A8: 2026/04/23 11:26:31 PM GMT+1 | B8: User_7 | C8: MTN | D8: Southwest Region | E8: Android | F8: 20-25 | G8: Often | H8: Messaging, Browsing | I8: Poor | J8: 1 | K8: Poor | L8: Always | M8: Slow internet, Call drops, No signal, Poor call quality | N8: Often | O8: Afternoon | P8: School/Work | Q8: Weak | R8: Severely | S8: No | T8: No | U8: Every time | V8: No | W8: Privacy, Security
A9: 2026/04/23 11:34:00 PM GMT+1 | B9: User_8 | C9: MTN, Orange, Camtel | D9: North West Region | E9: Android | F9: 20-25 | G9: Very often | H9: Social media, Messaging, Online classes/work, Browsing, Do surveys to help improve network | I9: Average | J9: 3 | K9: Average | L9: Sometimes | M9: Slow internet, Network outages | N9: Often | O9: Afternoon | P9: Everywhere | Q9: Moderate | R9: Moderately | S9: Yes | T9: Yes | U9: Every time | V9: Yes | W9: Privacy
A10: 2026/04/24 12:49:27 AM GMT+1 | B10: User_9 | C10: MTN, Orange | D10: North Region | E10: Android | F10: 25 and above | G10: Very often | H10: Social media, Video streaming, Messaging, Gaming | I10: Average | J10: 3 | K10: Average | L10: Sometimes | M10: No signal | N10: Sometimes | O10: Afternoon | P10: Everywhere | Q10: Moderate | R10: Severely | S10: No | T10: No | U10: Only when there is a problem | V10: No | W10: None
A11: 2026/04/24 12:54:34 AM GMT+1 | B11: User_10 | C11: MTN | D11: North West Region | E11: iPhone | F11: 15-20 | G11: Very often | H11: Classified | I11: Good | J11: 4 | K11: Good | L11: Never | M11: Slow internet | N11: Sometimes | O11: Afternoon | P11: School/Work | Q11: Moderate | R11: Severely | S11: Yes | T11: No | U11: Once a day | V11: No | W11: Privacy
A12: 2026/04/24 1:01:49 AM GMT+1 | B12: User_11 | C12: MTN | D12: Southwest Region | E12: iPhone | F12: 20-25 | G12: Very often | H12: Social media, Messaging | I12: Poor | J12: 3 | K12: Poor | L12: Often | M12: Slow internet, No signal, Poor call quality | N12: Sometimes | O12: Afternoon | P12: Everywhere | Q12: Moderate | R12: Moderately | S12: Yes | T12: No | U12: Only when there is a problem | V12: No | W12: Privacy
